Workbook
Name Do?um_tarihi: program!$A$7
Name Doðum_tarihi: program!$FZ$1
Name Excel_BuiltIn__FilterDatabase: program!$F$1:$F$300
Name Excel_BuiltIn__FilterDatabase: veri!$A$1:$K$138
Name Gün_Kayıbı: program!$H$1
Name Gün_kayýbý: program!$FW$1
Name Kaza_tarihi: program!#REF!
Name sanat_neden: program!$GD$1

Sheet veri
A1: Sicil No | B1: Adı | C1: Soyadı | D1: Doğum-tarihi | E1: Kaza-tarihi | F1: Saat | G1: Sanatı | H1: Yer | I1: Neden | J1: Uzuv | K1: Gün-Kayıbı | L1: Kazanın Kısa Açıklaması | N1: Y.A. İŞÇİ SAYISI | O1: Y.Ü. İŞÇİ SAYISI | Q1: Y.A. YEVMİYE SAYISI | R1: Y.Ü. YEVMİYE SAYISI | S1: TOPLAM YEVMİYE
A2: 986 | B2: ERHAN | C2: ÇİÇEK | D2: 28194 | E2: 45674 | F2: 0.76041667 | G2: 55 | H2: 32 | I2: 1130 | J2: 99 | K2: 0 | L2: 904 kapı numaralı PC 400 ekskavatörün; çalışma esnasmda motor kısmından alev yükselmesi | M2: Ocak | O2: 231 | R2: 4512 | S2: =R2 -> 4512
A3: 1051 | B3: METİN | C3: TURAN | D3: 14.05.1973 | E3: 14.06.2025 | F3: 0.50694444 | G3: 63 | H3: 42 | I3: 1990 | J3: 15 | K3: 0 | L3: Toplanma yerinde dinlenme esnasında dudağında meydana gelen kanama. | M3: Şubat | O3: 233 | R3: 4253 | S3: =R3 -> 4253
A4: 910 | B4: NAİM | C4: ÇAKAR | D4: 01.05.1978 | E4: 14.06.2025 | F4: 0.54166667 | G4: 70 | H4: 33 | I4: 460 | J4: 30 | K4: 0 | L4: Ekskavatör hidrolik pistonunu sökerken, basınçlı yağın kola vurması sonucunda sol kolda şişme. | M4: Mart | O4: 233 | R4: 4304 | S4: =R4 -> 4304
A5: 876 | B5: ERDOĞAN | C5: DEMİRTAŞ | D5: 08.02.1977 | E5: 20.06.2025 | F5: 0.5 | G5: 59 | H5: 41 | I5: 340 | J5: 45 | K5: 50 | L5: Sulama tankerinden inerken ayağını kırma. | M5: 3 AYLIK
A6: 921 | B6: SALİH | C6: YILDIZ | D6: 02.01.1978 | E6: 27.06.2025 | F6: 0.90972222 | G6: 53 | H6: 32 | I6: 1130 | J6: 99 | K6: 0 | L6: PC1100 Ekskavatör turbo bölümünde yangın çıkması, operatörde fiziki yaralanma yoktur. | M6: Nisan | O6: 234 | R6: 3713 | S6: =R6 -> 3713
A7: 364 | B7: FERDİ | C7: UZUN | D7: 16.02.1999 | E7: 21.07.2025 | F7: 0.50694444 | G7: 96 | H7: 35 | I7: 380 | J7: 52 | K7: 2 | L7: İşletme Müdürlüğümüz önündeki bankta otururken dengesini kaybederek sırt üstü düşmesİ. | M7: Mayıs | O7: 232 | R7: 4259 | S7: =R7 -> 4259
A8: 953 | B8: RECEP | C8: VARDAR | D8: 26.05.1982 | E8: 24.10.2025 | F8: 0.75347222 | G8: 55 | H8: 32 | I8: 340 | J8: 44 | K8: 26 | L8: 904 kapı nolu ekskavatörden inerken ayağını burkma | M8: Haziran | O8: 230 | R8: 3509 | S8: =R8 -> 3509
A9: 1061 | B9: EMRE | C9: ENGİN | D9: 19.07.1991 | E9: 25.11.2025 | F9: 0.42708333 | G9: 70 | H9: 33 | I9: 220 | J9: 45 | K9: 0 | L9: Takozun üzerindeki İş makinesi pistonunun takoz üzerinden sıyrılarak ayak üzerine düşmesi | M9: 6 AYLIK
A10: 928 | B10: HASAN NİHAT | C10: GEZER | D10: 27.10.1981 | E10: 01.12.2025 | F10: 0.51388889 | G10: 86 | H10: 33 | I10: 440 | J10: 30 | K10: 4 | L10: Elektrik atölyesi giriş kapısının köşebendine takılmas ısonucu sağ kolunda 3-5 cm kesik oluşması | M10: Temmuz | O10: 230 | R10: 3509 | S10: =R10 -> 3509
M11: Ağustos | O11: 230 | R11: 3509 | S11: =R11 -> 3509
M12: Eylül | O12: 227 | R12: 4283 | S12: =R12 -> 4283
M13: 9 AYLIK
M14: Ekim | O14: 226 | R14: 4462 | S14: =R14 -> 4462
M15: Kasım | O15: 226 | R15: 4166 | S15: =R15 -> 4166
M16: Aralık | O16: 228 | R16: 5173 | S16: =R16 -> 5173
O17: 228 | Q17: =SUM(Q2:Q16) -> 0 | R17: =SUM(R2:R4,R6:R8,R10:R12,R14:R16) -> 49652 | S17: =SUM(S2:S16) -> 49652

Sheet program
A1: {=veri!$D$1:$K$357} -> Doğum-tarihi | B1: Kaza-tarihi | C1: Saat | D1: Sanatı | E1: Yer | F1: Neden | G1: Uzuv | H1: Gün-Kayıbı | N1: KAZA YERİ | O1: ADET | P1: YERALTI SANATLARI | Q1: ADET | R1: YERÜSTÜ SANATLARI | S1: ADET | T1: AYRINTILI KAZA NEDENİ | U1: AÇIKLAMA / ALT ÖRNEKLER | V1: ADET | X1: KAZA TÜRÜ | Y1: SAYI | AE1: AY | AF1: ADET | AH1: GÜN | AI1: ADET | AK1: SAAT | AL1: ADET | AN1: YAŞ | AO1: ADET | AQ1: GÜN KAYBI | AR1: ADET | AS1: TOP.GÜN | AU1: ÖLÜ | AV1: YERALTI | AW1: YERÜSTÜ
A2: 28194 | B2: 45674 | C2: 0.76041667 | D2: 55 | E2: 32 | F2: 1130 | G2: 99 | H2: 0 | L2: Toplam Kazalı: | M2: =COUNTIF(D:D,">=1") -> 9 | N2: 11: Ayak İçi / Pano | O2: =COUNTIF(E:E,11) -> 0 | P2: 1: MEKANİZE KAZI OP. / Shearer Op. | Q2: =COUNTIF(D:D,1) -> 0 | R2: 51: DOZER OP. / Dozerci | S2: =COUNTIF(D:D,51) -> 0 | T2: 01 - GÖÇÜK / TAŞ-KÖMÜR DÜŞMESİ /KAYMA (Fall of Ground / Slide) | X2: Göçük / Taş-Kömür Düşmesi/Kayma | Y2: =SUM(V3:V9) -> 0 | AE2: Ocak | AF2: =SUMPRODUCT((MONTH(veri!E3:E497)=1)*(veri!E3:E497<>"")) -> 0 | AH2: Pazartesi | AI2: =SUMPRODUCT((WEEKDAY(veri!E3:E497,2)=1)*(veri!E3:E497<>"")) -> 2 | AK2: 0-2 | AL2: =COUNTIFS(veri!F:F,">="&0,veri!F:F,"<"&2) -> 9 | AN2: <=20 | AO2: =SUMPRODUCT(((veri!E3:E497-veri!D3:D497)/365.25<=20)*(veri!E3:E497<>"")) -> 0 | AQ2: 1-3 | AR2: =COUNTIFS(veri!K:K,">0",veri!K:K,"<=3") -> 1 | AS2: =SUMIFS(veri!K:K,veri!K:K,">0",veri!K:K,"<=3") -> 2 | AU2: Ölü sayısı | AV2: =COUNTIFS(veri!H:H,"<=22",veri!K:K,">=6000") -> 0 | AW2: =COUNTIFS(veri!H:H,">=31",veri!K:K,">=6000") -> 0
A3: 14.05.1973 | B3: 14.06.2025 | C3: 0.50694444 | D3: 63 | E3: 42 | F3: 1990 | G3: 15 | H3: 0 | L3: Yerüstü Kayıtlılar | M3: =COUNTIF(D:D,">50") -> 9 | N3: 12: Hazırlık Galerisi / Malz.Baca | O3: =COUNTIF(E:E,12) -> 0 | P3: 2: YÜR.TAHKİMAT SÜR. / Şilt Sürücü | Q3: =COUNTIF(D:D,2) -> 0 | R3: 52: EKSKAVATÖR OP. / Kepçeci | S3: =COUNTIF(D:D,52) -> 0 | T3: 0110: Tavandan taş/kömür düşmesi - Bump/Plaka | U3: Tavan taşı kopması, taş sekmesi, plaka düşmesi, kavlak düşmesi | V3: =COUNTIF(F:F,"=110") -> 0 | X3: Malzeme Düşmesi / Sıkışma / Ezilme | Y3: =SUM(V11:V17) -> 1 | AE3: Şubat | AF3: =SUMPRODUCT((MONTH(veri!E3:E497)=2)*(veri!E3:E497<>"")) -> 0 | AH3: Salı | AI3: =SUMPRODUCT((WEEKDAY(veri!E3:E497,2)=2)*(veri!E3:E497<>"")) -> 1 | AK3: 2-4 | AL3: =COUNTIFS(veri!F:F,">="&2,veri!F:F,"<"&4) -> 0 | AN3: 20-25 | AO3: =SUMPRODUCT(((veri!E3:E497-veri!D3:D497)/365.25>20)*((veri!E3:E497-veri!D3:D497)/365.25<=25)*(veri!E3:E497<>"")) -> 0 | AQ3: 3-7 | AR3: =COUNTIFS(veri!K:K,">3",veri!K:K,"<=7") -> 1 | AS3: =SUMIFS(veri!K:K,veri!K:K,">3",veri!K:K,"<=7") -> 4
A4: 01.05.1978 | B4: 14.06.2025 | C4: 0.54166667 | D4: 70 | E4: 33 | F4: 460 | G4: 30 | H4: 0 | L4: Yeraltı Kayıtlılar | M4: =M2-M3 -> 0 | N4: 13: Kömür Baca / Kömür Yolu | O4: =COUNTIF(E:E,13) -> 0 | P4: 3: Y.A.HAZ.İŞÇİSİ / Hazırlıkçı | Q4: =COUNTIF(D:D,3) -> 0 | R4: 53: İŞ MAK.OP. / Makine Operatörü | S4: =COUNTIF(D:D,53) -> 1 | T4: 0120: Yan duvar/kanat düşmesi - Rib fall | U4: Ayna kenarı, galeri yan duvarı çökmesi, rib düşmesi | V4: =COUNTIF(F:F,"=120") -> 0 | X4: Düşme (Kişi) / Kayma | Y4: =SUM(V19:V26) -> 3 | AE4: Mart | AF4: =SUMPRODUCT((MONTH(veri!E3:E497)=3)*(veri!E3:E497<>"")) -> 0 | AH4: Çarşamba | AI4: =SUMPRODUCT((WEEKDAY(veri!E3:E497,2)=3)*(veri!E3:E497<>"")) -> 0 | AK4: 4-6 | AL4: =COUNTIFS(veri!F:F,">="&4,veri!F:F,"<"&6) -> 0 | AN4: 25-30 | AO4: =SUMPRODUCT(((veri!E3:E497-veri!D3:D497)/365.25>25)*((veri!E3:E497-veri!D3:D497)/365.25<=30)*(veri!E3:E497<>"")) -> 1 | AQ4: 7-15 | AR4: =COUNTIFS(veri!K:K,">7",veri!K:K,"<=15") -> 0 | AS4: =SUMIFS(veri!K:K,veri!K:K,">7",veri!K:K,"<=15") -> 0
A5: 08.02.1977 | B5: 20.06.2025 | C5: 0.5 | D5: 59 | E5: 41 | F5: 340 | G5: 45 | H5: 50 | N5: 14: Ana İhraç Yolu / Galeri | O5: =COUNTIF(E:E,14) -> 0 | P5: 4: Y.A.HAZ.İŞÇ.YEDEK | Q5: =COUNTIF(D:D,4) -> 0 | R5: 54: GREYDER OP. / Greyderci | S5: =COUNTIF(D:D,54) -> 0 | T5: 0130: Ayna göçüğü / Ayna düşmesi | U5: Kazı aynasından kopma, ayna çökmesi | V5: =COUNTIF(F:F,"=130") -> 0 | X5: Çarpma / Vurma / Batma | Y5: =SUM(V28:V34) -> 2 | AE5: Nisan | AF5: =SUMPRODUCT((MONTH(veri!E3:E497)=4)*(veri!E3:E497<>"")) -> 0 | AH5: Perşembe | AI5: =SUMPRODUCT((WEEKDAY(veri!E3:E497,2)=4)*(veri!E3:E497<>"")) -> 0 | AK5: 6-8 | AL5: =COUNTIFS(veri!F:F,">="&6,veri!F:F,"<"&8) -> 0 | AN5: 30-35 | AO5: =SUMPRODUCT(((veri!E3:E497-veri!D3:D497)/365.25>30)*((veri!E3:E497-veri!D3:D497)/365.25<=35)*(veri!E3:E497<>"")) -> 1 | AQ5: 15-30 | AR5: =COUNTIFS(veri!K:K,">15",veri!K:K,"<=30") -> 1 | AS5: =SUMIFS(veri!K:K,veri!K:K,">15",veri!K:K,"<=30") -> 26
A6: 02.01.1978 | B6: 27.06.2025 | C6: 0.90972222 | D6: 53 | E6: 32 | F6: 1130 | G6: 99 | H6: 0 | L6: Yerüstü Kazası | M6: =COUNTIF(E:E,">30") -> 9 | N6: 15: Bant Boyu / Konveyör Yolu | O6: =COUNTIF(E:E,15) -> 0 | P6: 5: Y.A.HAZ.USTASI / Ekip Başı | Q6: =COUNTIF(D:D,5) -> 0 | R6: 55: YÜKLEYİCİ OP. / Loderci | S6: =COUNTIF(D:D,55) -> 2 | T6: 0160: Topuk/Ayak göçüğü - Longwall | U6: Uzunayak topuk göçmesi, pano içi toprak kayması | V6: =COUNTIF(F:F,"=160") -> 0 | X6: Motorlu Nakliye / Araç Kazası | Y6: =SUM(V36:V42) -> 0 | AE6: Mayıs | AF6: =SUMPRODUCT((MONTH(veri!E3:E497)=5)*(veri!E3:E497<>"")) -> 0 | AH6: Cuma | AI6: =SUMPRODUCT((WEEKDAY(veri!E3:E497,2)=5)*(veri!E3:E497<>"")) -> 3 | AK6: 8-10 | AL6: =COUNTIFS(veri!F:F,">="&8,veri!F:F,"<"&10) -> 0 | AN6: 35-40 | AO6: =SUMPRODUCT(((veri!E3:E497-veri!D3:D497)/365.25>35)*((veri!E3:E497-veri!D3:D497)/365.25<=40)*(veri!E3:E497<>"")) -> 0 | AQ6: >30 | AR6: =COUNTIFS(veri!K:K,">30",veri!K:K,"<=6000") -> 1 | AS6: =SUMIFS(veri!K:K,veri!K:K,">30",veri!K:K,"<=6000") -> 50
A7: 16.02.1999 | B7: 21.07.2025 | C7: 0.50694444 | D7: 96 | E7: 35 | F7: 380 | G7: 52 | H7: 2 | L7: Yeraltı Kazası | M7: =M2-M6 -> 0 | N7: 16: Kuyu / Eğimli Kuyu | O7: =COUNTIF(E:E,16) -> 0 | P7: 6: Y.A.MAD.HAZ.ELEM. | Q7: =COUNTIF(D:D,6) -> 0 | R7: 56: FORKLİFT OP. / Forkliftçi | S7: =COUNTIF(D:D,56) -> 0 | T7: 0170: Açık ocak şev kayması / Göçüğü | U7: Highwall kayması, basamak göçüğü, şev hareketi | V7: =COUNTIF(F:F,"=170") -> 0 | X7: Motorsuz Nakliye / El Arabası | Y7: =SUM(V44:V46) -> 0 | AE7: Haziran | AF7: =SUMPRODUCT((MONTH(veri!E3:E497)=6)*(veri!E3:E497<>"")) -> 4 | AH7: Cumartesi | AI7: =SUMPRODUCT((WEEKDAY(veri!E3:E497,2)=6)*(veri!E3:E497<>"")) -> 2 | AK7: 10-12 | AL7: =COUNTIFS(veri!F:F,">="&10,veri!F:F,"<"&12) -> 0 | AN7: 40-45 | AO7: =SUMPRODUCT(((veri!E3:E497-veri!D3:D497)/365.25>40)*((veri!E3:E497-veri!D3:D497)/365.25<=45)*(veri!E3:E497<>"")) -> 2 | AQ7: TOPLAM | AR7: =SUM(AR2:AR6) -> 4 | AS7: =SUM(AS2:AS6) -> 82
A8: 26.05.1982 | B8: 24.10.2025 | C8: 0.75347222 | D8: 55 | E8: 32 | F8: 340 | G8: 44 | H8: 26 | N8: 17: Vinç Altı / Pompa İst. | O8: =COUNTIF(E:E,17) -> 0 | P8: 7: BEDEN İŞÇ.(Y.A.) / Amele | Q8: =COUNTIF(D:D,7) -> 0 | R8: 57: VİNÇ OP. / Vinççi | S8: =COUNTIF(D:D,57) -> 0 | T8: 0180: Dolgu/Tavan arası çökmesi | U8: Dolgu malzemesi akması, tavan arası göçük | V8: =COUNTIF(F:F,"=180") -> 0 | X8: Vinç / Kaldırma | Y8: =SUM(V48:V52) -> 0 | AE8: Temmuz | AF8: =SUMPRODUCT((MONTH(veri!E3:E497)=7)*(veri!E3:E497<>"")) -> 1 | AH8: Pazar | AI8: =SUMPRODUCT((WEEKDAY(veri!E3:E497,2)=7)*(veri!E3:E497<>"")) -> 0 | AK8: 12-14 | AL8: =COUNTIFS(veri!F:F,">="&12,veri!F:F,"<"&14) -> 0 | AN8: 45-50 | AO8: =SUMPRODUCT(((veri!E3:E497-veri!D3:D497)/365.25>45)*((veri!E3:E497-veri!D3:D497)/365.25<=50)*(veri!E3:E497<>"")) -> 3
A9: 19.07.1991 | B9: 25.11.2025 | C9: 0.42708333 | D9: 70 | E9: 33 | F9: 220 | G9: 45 | H9: 0 | L9: Toplam Gün Kaybı | M9: =SUM(H2:H500) -> 82 | N9: 18: Tertip Odası / Beke | O9: =COUNTIF(E:E,18) -> 0 | P9: 8: DELİKÇİ / Perforatörcü | Q9: =COUNTIF(D:D,8) -> 0 | R9: 58: KAMYON ŞOF. / Damperci | S9: =COUNTIF(D:D,58) -> 0 | T9: 0190: Diğer göçük/düşme olayları | U9: Sınıflandırılamayan göçük olayları | V9: =COUNTIF(F:F,"=190") -> 0 | X9: Makine Kazası / Ekipman | Y9: =SUM(V54:V61) -> 0 | AE9: Ağustos | AF9: =SUMPRODUCT((MONTH(veri!E3:E497)=8)*(veri!E3:E497<>"")) -> 0 | AH9: TOPLAM | AI9: =SUM(AI2:AI8) -> 8 | AK9: 14-16 | AL9: =COUNTIFS(veri!F:F,">="&14,veri!F:F,"<"&16) -> 0 | AN9: >50 | AO9: =SUMPRODUCT(((veri!E3:E497-veri!D3:D497)/365.25>50)*(veri!E3:E497<>"")) -> 1 | AQ9: GÜN KAYBI | AR9: YERALTI | AS9: YERÜSTÜ
A10: 27.10.1981 | B10: 01.12.2025 | C10: 0.51388889 | D10: 86 | E10: 33 | F10: 440 | G10: 30 | H10: 4 | N10: 19: Kavşak / Sapak Noktası | O10: =COUNTIF(E:E,19) -> 0 | P10: 9: ATEŞÇİ / Dinamitçi | Q10: =COUNTIF(D:D,9) -> 0 | R10: 59: KAYA KAM.OP. / Ağır Kamyon | S10: =COUNTIF(D:D,59) -> 1 | T10: 02 - MALZEME DÜŞMESİ / SIKIŞMA / EZİLME (Struck By) | X10: Elektrik Kazası | Y10: =SUM(V63:V66) -> 0 | AE10: Eylül | AF10: =SUMPRODUCT((MONTH(veri!E3:E497)=9)*(veri!E3:E497<>"")) -> 0 | AK10: 16-18 | AL10: =COUNTIFS(veri!F:F,">="&16,veri!F:F,"<"&18) -> 0 | AN10: TOPLAM | AO10: =SUM(AO2:AO9) -> 8 | AQ10: Toplam gün | AR10: =SUMIFS(veri!K:K,veri!H:H,"<=22") -> 0 | AS10: =SUMIFS(veri!K:K,veri!H:H,">=31") -> 82
A11: 0 | B11: 0 | C11: 0 | D11: 0 | E11: 0 | F11: 0 | G11: 0 | H11: 0 | N11: 20: Havalandırma / Kaçamak Yolu | O11: =COUNTIF(E:E,20) -> 0 | P11: 10: ZEM.DELGİ MAK.OP. / Boltçu | Q11: =COUNTIF(D:D,10) -> 0 | R11: 60: ŞOFÖR / Servis Şoförü | S11: =COUNTIF(D:D,60) -> 0 | T11: 0210: Malzeme arası sıkışma - El/Parmak | U11: Bağ, oluk, kama, boyunduruk arasına el/parmak sıkışması | V11: =COUNTIF(F:F,"=210") -> 0 | X11: Gaz-Toz Patlaması / Grizu | Y11: =SUM(V68:V72) -> 0 | AE11: Ekim | AF11: =SUMPRODUCT((MONTH(veri!E3:E497)=10)*(veri!E3:E497<>"")) -> 1 | AK11: 18-20 | AL11: =COUNTIFS(veri!F:F,">="&18,veri!F:F,"<"&20) -> 0
A12: 0 | B12: 0 | C12: 0 | D12: 0 | E12: 0 | F12: 0 | G12: 0 | H12: 0 | N12: 21: Dolgu / Tavan Arası | O12: =COUNTIF(E:E,21) -> 0 | P12: 11: TAHKİMATÇI / Bağcı-Direkçi | Q12: =COUNTIF(D:D,11) -> 0 | R12: 61: TESİS İŞÇ. / Kırıcı Op. | S12: =COUNTIF(D:D,61) -> 0 | T12: 0220: Makine/ekipman parçası düşmesi | U12: Makine parçası, el aleti üzerine düşmesi | V12: =COUNTIF(F:F,"=220") -> 1 | X12: Yangın | Y12: =SUM(V74:V79) -> 2 | AE12: Kasım | AF12: =SUMPRODUCT((MONTH(veri!E3:E497)=11)*(veri!E3:E497<>"")) -> 1 | AK12: 20-22 | AL12: =COUNTIFS(veri!F:F,">="&20,veri!F:F,"<"&22) -> 0
A13: 0 | B13: 0 | C13: 0 | D13: 0 | E13: 0 | F13: 0 | G13: 0 | H13: 0 | N13: 22: YA Diğer | O13: =COUNTIF(E:E,22) -> 0 | P13: 12: KONVEYÖR OP. / Bantçı | Q13: =COUNTIF(D:D,12) -> 0 | R13: 62: TESİS İŞÇ.2 / Tesis Yrd. | S13: =COUNTIF(D:D,62) -> 0 | T13: 0230: Tahkimat malzemesi düşmesi | U13: Kama düşmesi, direk kayması, tahkimat montajı sırasında | V13: =COUNTIF(F:F,"=230") -> 0 | X13: Su Baskını / İnündasyon | Y13: =SUM(V81:V84) -> 0 | AE13: Aralık | AF13: =SUMPRODUCT((MONTH(veri!E3:E497)=12)*(veri!E3:E497<>"")) -> 1 | AK13: 22-24 | AL13: =COUNTIFS(veri!F:F,">="&22,veri!F:F,"<"&24) -> 0
A14: 0 | B14: 0 | C14: 0 | D14: 0 | E14: 0 | F14: 0 | G14: 0 | H14: 0 | N14: 31: Tesisler / Kırıcı-Silo-Tikiner | O14: =COUNTIF(E:E,31) -> 0 | P14: 13: MONORAY OP. / Kulikar Op. | Q14: =COUNTIF(D:D,13) -> 0 | R14: 63: MANEVRACI / Harmancı | S14: =COUNTIF(D:D,63) -> 1 | T14: 0240: Dönen/hareketli parçaya kapılma | U14: Mil, kayış, dişli, konveyör ruloya kapılma | V14: =COUNTIF(F:F,"=240") -> 0 | X14: Patlayıcı Madde / Dinamit | Y14: =SUM(V86:V90) -> 0 | AE14: TOPLAM | AF14: =SUM(AF2:AF13) -> 8 | AK14: TOPLAM | AL14: =SUM(AL2:AL13) -> 9
A15: 0 | B15: 0 | C15: 0 | D15: 0 | E15: 0 | F15: 0 | G15: 0 | H15: 0 | N15: 32: Açık Ocak / Şev Kenarı | O15: =COUNTIF(E:E,32) -> 3 | P15: 14: DESANDRE VİNÇÇİSİ / Vinççi | Q15: =COUNTIF(D:D,14) -> 0 | R15: 64: KANTAR GÖR. / Kantarcı | S15: =COUNTIF(D:D,64) -> 0 | T15: 0250: Konveyör/bant kazası - Kapılma | U15: Bant sistemine kapılma, bant kayışı kopması, ürün sıkışması | V15: =COUNTIF(F:F,"=250") -> 0 | X15: Elle Taşıma / Zorlanma / Burkulma | Y15: =SUM(V92:V95) -> 0
A16: 0 | B16: 0 | C16: 0 | D16: 0 | E16: 0 | F16: 0 | G16: 0 | H16: 0 | N16: 33: Atölyeler / Kaynakhane | O16: =COUNTIF(E:E,33) -> 3 | P16: 15: MALZ.TAK.DAĞ.İŞÇ. / Malzemeci | Q16: =COUNTIF(D:D,15) -> 0 | R16: 65: NUMUNECİ / Numune Alma El. | S16: =COUNTIF(D:D,65) -> 0 | T16: 0260: Yükleme/boşaltma sırasında ezilme | U16: Araç-malzeme arasına sıkışma, damper altında kalma | V16: =COUNTIF(F:F,"=260") -> 0 | X16: Mahsur Kalma / Entrapment | Y16: =SUM(V97:V100) -> 0
A17: 0 | B17: 0 | C17: 0 | D17: 0 | E17: 0 | F17: 0 | G17: 0 | H17: 0 | N17: 34: Pazarlama / Kantar Sahası | O17: =COUNTIF(E:E,34) -> 0 | P17: 16: TAMİR BAKIM USTA / Mekanikçi | Q17: =COUNTIF(D:D,16) -> 0 | R17: 66: BEDEN İŞÇ.(Y.Ü.) / Amele | S17: =COUNTIF(D:D,66) -> 0 | T17: 0270: Diğer malzeme düşmesi/sıkışma | U17: Sınıflandırılamayan sıkışma/ezilme olayları | V17: =COUNTIF(F:F,"=270") -> 0 | X17: Sıcak Çalışma / Kaynak | Y17: =SUM(V102:V105) -> 0
A18: 0 | B18: 0 | C18: 0 | D18: 0 | E18: 0 | F18: 0 | G18: 0 | H18: 0 | N18: 35: Sosyal Tes. / İdari Bina | O18: =COUNTIF(E:E,35) -> 1 | P18: 17: ELEKTRİKÇİ(Y.A.) | Q18: =COUNTIF(D:D,17) -> 0 | R18: 67: TAH.TAH.İŞÇ. / Yükçü | S18: =COUNTIF(D:D,67) -> 0 | T18: 03 - DÜŞME KİŞİ (Slip or Fall of Person) | X18: Sağlık Sorunu / İşyerinde | Y18: =SUM(V107:V115) -> 0
A19: 0 | B19: 0 | C19: 0 | D19: 0 | E19: 0 | F19: 0 | G19: 0 | H19: 0 | N19: 36: Servis Yolu / Ulaşım | O19: =COUNTIF(E:E,36) -> 0 | P19: 18: EL.ELEK.TEK. / Otomasyon Tek. | Q19: =COUNTIF(D:D,18) -> 0 | R19: 68: AKARYAKIT SOR. / Yakıt İst.Şefi | S19: =COUNTIF(D:D,68) -> 0 | T19: 0310: Yürürken düşme / Aynı seviye | U19: Yürürken kayma, ıslak/çamurlu zeminde kayarak düşme, ayak burkması sonrası düşme | V19: =COUNTIF(F:F,"=310") -> 0 | X19: Basınçlı Kap Patl. / Hortum | Y19: =SUM(V117:V120) -> 0
A20: 0 | B20: 0 | C20: 0 | D20: 0 | E20: 0 | F20: 0 | G20: 0 | H20: 0 | N20: 37: Laboratuvar / Numune Haz. | O20: =COUNTIF(E:E,37) -> 0 | P20: 19: TULUMBACI / Pompacı | Q20: =COUNTIF(D:D,19) -> 0 | R20: 69: AKARYAKIT DOL. / Pompacı-Yakıtçı | S20: =COUNTIF(D:D,69) -> 0 | T20: 0320: Yüksekten düşme - Platform/Merdiven | U20: Merdivenden, stok yığınından, basamaktan, platform, iskeleden düşme | V20: =COUNTIF(F:F,"=320") -> 0 | X20: Diğer Nedenler | Y20: =SUM(V122:V129) -> 1
A21: 0 | B21: 0 | C21: 0 | D21: 0 | E21: 0 | F21: 0 | G21: 0 | H21: 0 | N21: 38: Pasa Döküm / Stok Sahası | O21: =COUNTIF(E:E,38) -> 0 | P21: 20: KUM.MERKEZİ OP. / Panel Op. | Q21: =COUNTIF(D:D,20) -> 0 | R21: 70: İŞ MAK.BAK.ON. / Ağır Mak.Tam. | S21: =COUNTIF(D:D,70) -> 2 | T21: 0330: Boşluğa/kanala düşme - Hendek | U21: Su kanalı, kulikar yolu boşluğu, hendek, çukur | V21: =COUNTIF(F:F,"=330") -> 0 | X21: TOPLAM | Y21: =SUM(Y2:Y20) -> 9
A22: 0 | B22: 0 | C22: 0 | D22: 0 | E22: 0 | F22: 0 | G22: 0 | H22: 0 | N22: 39: Malzeme Deposu / Ambar | O22: =COUNTIF(E:E,39) -> 0 | P22: 21: İŞL.ELEK.BAKIMCI | Q22: =COUNTIF(D:D,21) -> 0 | R22: 71: İŞ MAK.BAK.ON.2 / Mek.Çırağı | S22: =COUNTIF(D:D,71) -> 0 | T22: 0340: Araçtan/iş makinesinden düşme | U22: Kamyon, iş makinesi, servis, kulikar, monoray, araçtan inerken/binerken düşme | V22: =COUNTIF(F:F,"=340") -> 2
A23: 0 | B23: 0 | C23: 0 | D23: 0 | E23: 0 | F23: 0 | G23: 0 | H23: 0 | N23: 40: Bant Hattı (Yerüstü) | O23: =COUNTIF(E:E,40) -> 0 | P23: 22: MADEN TEKNİKERİ / Tek.Gözetmen | Q23: =COUNTIF(D:D,22) -> 0 | R23: 72: MEK.BAK.ON. / Mekanikçi | S23: =COUNTIF(D:D,72) -> 0 | T23: 0350: Kuyu/eğimli kuyu içi düşme | U23: Kuyu, bacada kayma/düşme, skip üzerinden düşme | V23: =COUNTIF(F:F,"=350") -> 0
A24: 0 | B24: 0 | C24: 0 | D24: 0 | E24: 0 | F24: 0 | G24: 0 | H24: 0 | N24: 41: Park / Garaj Sahası | O24: =COUNTIF(E:E,41) -> 1 | P24: 23: ÖLÇÜ TESPİT ELEM. / Ölçücü | Q24: =COUNTIF(D:D,23) -> 0 | R24: 73: MEK.BAK.ON.2 / Mek.Yrd. | S24: =COUNTIF(D:D,73) -> 0 | T24: 0360: Duran nesneye çarpıp/takılıp düşme - Ray/Kablo | U24: Raylar, hortumlar, kablolara takılıp düşme, duran nesneye çarpıp düşme | V24: =COUNTIF(F:F,"=360") -> 0
A25: 0 | B25: 0 | C25: 0 | D25: 0 | E25: 0 | F25: 0 | G25: 0 | H25: 0 | N25: 42: YÜ Diğer | O25: =COUNTIF(E:E,42) -> 1 | P25: 24: ÖLÇÜ TESPİT SOR. / Markşayder | Q25: =COUNTIF(D:D,24) -> 0 | R25: 74: KAYNAKÇI / Kaynak Ustası | S25: =COUNTIF(D:D,74) -> 0 | T25: 0370: El aleti ile çalışırken düşme | U25: El aleti çalışırken düşme | V25: =COUNTIF(F:F,"=370") -> 0
A26: 0 | B26: 0 | C26: 0 | D26: 0 | E26: 0 | F26: 0 | G26: 0 | H26: 0 | N26: TOPLAM | O26: =SUM(O2:O25) -> 9 | P26: 25: NEZARETÇİ / Vardiya Amiri | Q26: =COUNTIF(D:D,25) -> 0 | R26: 75: SOĞUK DEMİRCİ / Demirci | S26: =COUNTIF(D:D,75) -> 0 | T26: 0380: Diğer kişi düşme olayları | U26: Sınıflandırılamayan düşme olayları | V26: =COUNTIF(F:F,"=380") -> 1
A27: 0 | B27: 0 | C27: 0 | D27: 0 | E27: 0 | F27: 0 | G27: 0 | H27: 0 | P27: 26: Y.A.İSG DESTEK EL. / Gaz Ölçümcü | Q27: =COUNTIF(D:D,26) -> 0 | R27: 76: TESVİYECİ / Tesviye Ustası | S27: =COUNTIF(D:D,76) -> 0 | T27: 04 - ÇARPMA / VURMA / BATMA (Striking / Bumping)
A28: 0 | B28: 0 | C28: 0 | D28: 0 | E28: 0 | F28: 0 | G28: 0 | H28: 0 | N28: KAZALANAN UZUV | O28: ADET | P28: YA TOPLAM | Q28: =SUM(Q2:Q27) -> 0 | R28: 77: TORNACI / Torna Op. | S28: =COUNTIF(D:D,77) -> 0 | T28: 0410: Aletle çalırıken kendine vurma, sıkıştırma, çarpma, kesme | U28: Kazma ters dönmesi, anahtar vurması, levye kayması, aletle çalırışırken kendine vurmak | V28: =COUNTIF(F:F,"=410") -> 0
A29: 0 | B29: 0 | C29: 0 | D29: 0 | E29: 0 | F29: 0 | G29: 0 | H29: 0 | N29: 10: BAŞ (Genel) | O29: =COUNTIF(G:G,10) -> 0 | R29: 78: FREZECİ / Freze Op. | S29: =COUNTIF(D:D,78) -> 0 | T29: 0420: Makine/iş makinesi çarpması | U29: Kepçenin ani hareketi, makine kolu çarpması | V29: =COUNTIF(F:F,"=420") -> 0
A30: 0 | B30: 0 | C30: 0 | D30: 0 | E30: 0 | F30: 0 | G30: 0 | H30: 0 | N30: 11: Kafa/Kafatası | O30: =COUNTIF(G:G,11) -> 0 | R30: 79: DÖK.MODELCİSİ / Kalıpçı | S30: =COUNTIF(D:D,79) -> 0 | T30: 0430: Tel/çapak/kıymık batması | U30: Hasır tel, çapak sıçraması | V30: =COUNTIF(F:F,"=430") -> 0
A31: 0 | B31: 0 | C31: 0 | D31: 0 | E31: 0 | F31: 0 | G31: 0 | H31: 0 | N31: 12: Göz | O31: =COUNTIF(G:G,12) -> 0 | R31: 80: MARANGOZ / Doğramacı | S31: =COUNTIF(D:D,80) -> 0 | T31: 0440: Sabit nesneye çarpma - Tavan/Dikme/Kama | U31: Alçak tavana/dikmeleye kafa çarpma, galeri köşesine çarpma | V31: =COUNTIF(F:F,"=440") -> 1
A32: 0 | B32: 0 | C32: 0 | D32: 0 | E32: 0 | F32: 0 | G32: 0 | H32: 0 | N32: 13: Kulak | O32: =COUNTIF(G:G,13) -> 0 | R32: 81: RADYATÖR TAM. / Radyatörcü | S32: =COUNTIF(D:D,81) -> 0 | T32: 0450: Fırlayan/sıçrayan parça - Halat/Zincir | U32: Kırılan zincir, kopan halat, fırlayan parça | V32: =COUNTIF(F:F,"=450") -> 0
A33: 0 | B33: 0 | C33: 0 | D33: 0 | E33: 0 | F33: 0 | G33: 0 | H33: 0 | N33: 14: Burun | O33: =COUNTIF(G:G,14) -> 0 | R33: 82: OTO.ELEKTRİKÇİ / Araç Elek. | S33: =COUNTIF(D:D,82) -> 0 | T33: 0460: Basınçlı madde/su sıçraması - Hidrolik | U33: Hidrolik yağ, su, hava sıçraması/patlaması | V33: =COUNTIF(F:F,"=460") -> 1
A34: 0 | B34: 0 | C34: 0 | D34: 0 | E34: 0 | F34: 0 | G34: 0 | H34: 0 | N34: 15: Yüz/Çene/Alın | O34: =COUNTIF(G:G,15) -> 1 | R34: 83: BOYACI / Boya Ustası | S34: =COUNTIF(D:D,83) -> 0 | T34: 0470: Diğer çarpma/vurma olayları | U34: Sınıflandırılamayan çarpma olayları | V34: =COUNTIF(F:F,"=470") -> 0
A35: 0 | B35: 0 | C35: 0 | D35: 0 | E35: 0 | F35: 0 | G35: 0 | H35: 0 | N35: 20: BOYUN | O35: =COUNTIF(G:G,20) -> 0 | R35: 84: İNŞAAT İŞÇ. / Betoncu | S35: =COUNTIF(D:D,84) -> 0 | T35: 05 - MOTORLU NAKLİYE / ARAÇ (Powered Haulage)
A36: 0 | B36: 0 | C36: 0 | D36: 0 | E36: 0 | F36: 0 | G36: 0 | H36: 0 | N36: 30: KOL (Genel) | O36: =COUNTIF(G:G,30) -> 2 | R36: 85: İNŞAAT USTA / Kalfa | S36: =COUNTIF(D:D,85) -> 0 | T36: 0510: Servis aracı kazası - Devrilme | U36: Devrilme, çarpışma, olumsuz hava/yol koşulları, araç kapısına sıkışma | V36: =COUNTIF(F:F,"=510") -> 0
A37: 0 | B37: 0 | C37: 0 | D37: 0 | E37: 0 | F37: 0 | G37: 0 | H37: 0 | N37: 31: Omuz/Kürek Kemiği | O37: =COUNTIF(G:G,31) -> 0 | R37: 86: ELEKTRİK TEK. / Elek.Teknisyen | S37: =COUNTIF(D:D,86) -> 1 | T37: 0520: İş makinası kazası - Dozer/Ekskavatör | U37: Ekskavatör, dozer, loder kazası, devrilme | V37: =COUNTIF(F:F,"=520") -> 0
A38: 0 | B38: 0 | C38: 0 | D38: 0 | E38: 0 | F38: 0 | G38: 0 | H38: 0 | N38: 32: Üst Kol | O38: =COUNTIF(G:G,32) -> 0 | R38: 87: ELEKTRONİK TEK. / Elektronikçi | S38: =COUNTIF(D:D,87) -> 0 | T38: 0530: Maden kamyonu kazası - Damperli | U38: Damperli kamyon, arazöz, petrol tankeri, bakım aracı kazası | V38: =COUNTIF(F:F,"=530") -> 0
A39: 0 | B39: 0 | C39: 0 | D39: 0 | E39: 0 | F39: 0 | G39: 0 | H39: 0 | N39: 33: Dirsek | O39: =COUNTIF(G:G,33) -> 0 | R39: 88: HARİTA TEK. / Haritacı | S39: =COUNTIF(D:D,88) -> 0 | T39: 0540: Vagon/araba kayması - Fren | U39: Ray üstü vagonun kayması, araba freni tutmaması | V39: =COUNTIF(F:F,"=540") -> 0
A40: 0 | B40: 0 | C40: 0 | D40: 0 | E40: 0 | F40: 0 | G40: 0 | H40: 0 | N40: 34: Ön Kol | O40: =COUNTIF(G:G,34) -> 0 | R40: 89: HARİTA TEKN. / Ölçüm Tekn. | S40: =COUNTIF(D:D,89) -> 0 | T40: 0550: Kulikar/monoray kazası | U40: Yeraltı yükleyici-taşıyıcı araç kazaları | V40: =COUNTIF(F:F,"=550") -> 0
...

Sheet kontrol
A1: UZUV-GÜN | B1: KAZA-UZUV
A2: =uzuvgün!B37 -> 9 | B2: =kazatürüuzuv!AK24 -> 0 | D2: =IF(A2=B2,"uzuv-gün ve kazatürü-uzuv tabloları birbirini doğruluyor","HATA!") -> HATA!
A3: =uzuvgün!B4 -> 0 | B3: =kazatürüuzuv!B24 -> 0 | D3: =IF(A3=B3,"baş; tamam","baş; hata var") -> baş; tamam
A4: =uzuvgün!B10 -> 0 | B4: =kazatürüuzuv!H24 -> 0 | D4: =IF(A4=B4,"boyun; tamam","boyun; hata var") -> boyun; tamam
A5: =uzuvgün!B11 -> 2 | B5: =kazatürüuzuv!I24 -> 0 | D5: =IF(A5=B5,"kol; tamam","kol; hata var") -> kol; hata var
A6: =uzuvgün!B17 -> 0 | B6: =kazatürüuzuv!O24 -> 0 | D6: =IF(A6=B6,"el; tamam","el; hata var") -> el; tamam
A7: =uzuvgün!B19 -> 0 | B7: =kazatürüuzuv!Q24 -> 0 | D7: =IF(A7=B7,"bacak; tamam","bacak; hata var") -> bacak; tamam
A8: =uzuvgün!B21 -> 0 | B8: =kazatürüuzuv!S24 -> 0 | D8: =IF(A8=B8,"diz; tamam","diz; hata var") -> diz; tamam
A9: =uzuvgün!B26 -> 0 | B9: =kazatürüuzuv!X24 -> 0 | D9: =IF(A9=B9,"gövde; tamam","gövde; hata var") -> gövde; tamam
A11: TABLOLARDAKI "TOPLAM" RAKAMLARININ KARŞILAŞTIRMASI
A13: Kaza türü | C13: =kazatürü!C137 -> 0 | D13: =IF(AND(C13=C14,C14=C15,C15=C16,C16=C17,C17=C18,C18=C19,C19=C20,C20=C21,C21=C22,C22=C23),"TÜM TABLOLAR TUTARLI ✓","HATA VAR!") -> HATA VAR!
A14: Kaza türü-yeri | C14: =kazatürüyer!Z24 -> 0
A15: Kaza türü-sanat | C15: =sanatkazatürü!CG24 -> 0
A16: Kaza yeri-sanat | C16: =sanatyer!Z87 -> 9
A17: Kaza türü-uzuv | C17: =kazatürüuzuv!AK24 -> 0
A18: Aylar-kazalı | C18: =zaman!B16 -> 8
A19: Günler-kazalı | C19: =zaman!F11 -> 8
A20: Saat-kazalı | C20: =zaman!J16 -> 9
A21: Uzuv-kazalı | C21: =uzuvgün!B37 -> 9
A22: Gün kayıbı-kazalı | C22: =uzuvgün!F9 -> 4
A23: Yaş-kazalı | C23: =yas!B11 -> 8
A26: Göçük-sanat | C26: =göcük!CE13 -> 0
A27: Elle taşıma-sanat | C27: =elletasima!CE9 -> 0
A28: Düşme-sanat | C28: =düsme!CE12 -> 3

Sheet Genel
B3: ÇLİ - 2024
A6: ÖZET BİLGİLER
B11: Yeraltı | C11: Yerüstü | D11: Toplam
A13: Yaralı: | B13: =SUM(kazatürüyer!B24:M24)-B14 -> 0 | C13: =SUM(kazatürüyer!N24:Y24)-C14 -> 0 | D13: =B13+C13 -> 0
A14: Ölü: | B14: =program!AV2 -> 0 | C14: =program!AW2 -> 0 | D14: =B14+C14 -> 0
A15: Toplam kazalı: | B15: =B13+B14 -> 0 | C15: =C13+C14 -> 0 | D15: =B15+C15 -> 0
A17: İşçi Sayısı: | B17: =AVERAGE(veri!N2:N4,veri!N6:N8,veri!N10:N12,veri!N14:N16) -> #DIV/0! | C17: =AVERAGE(veri!O2:O4,veri!O6:O8,veri!O10:O12,veri!O14:O16) -> 230 | D17: =B17+C17 -> #DIV/0!
A18: Fiili yevmiye sayısı: | B18: =veri!Q17 -> 0 | C18: =veri!R17 -> 49652 | D18: =B18+C18 -> 49652
A19: Toplam çalışma saati: | B19: =B18*8 -> 0 | C19: =C18*8 -> 397216 | D19: =B19+C19 -> 397216
A20: Toplam iş günü kaybı: | B20: =program!AR10 -> 0 | C20: =program!AS10 -> 82 | D20: =B20+C20 -> 82
A22: İşçi sayısı / kazalı: | B22: =IFERROR(B17/B15,0) -> 0 | C22: =IFERROR(C17/C15,0) -> 0 | D22: =IFERROR(D17/D15,0) -> 0
A24: İş günü kaybı / kazalı: | B24: =IFERROR(B20/B15,0) -> 0 | C24: =IFERROR(C20/C15,0) -> 0 | D24: =IFERROR(D20/D15,0) -> 0
A26: Kaza ağırlık oranı: | B26: =IFERROR(B20*1000/B19,0) -> 0 | C26: =IFERROR(C20*1000/C19,0) -> 0.2064368 | D26: =IFERROR(D20*1000/D19,0) -> 0.2064368
A28: Kaza sıklık oranı: | B28: =IFERROR(B15*1000000/B19,0) -> 0 | C28: =IFERROR(C15*1000000/C19,0) -> 0 | D28: =IFERROR(D15*1000000/D19,0) -> 0
A30: Satılabilir üretim (ton):
A31: Üretim/kazalı (t./kaza.): | B31: =IFERROR(B30/B15,0) -> 0 | C31: =IFERROR(C30/C15,0) -> 0 | D31: =IFERROR(D30/D15,0) -> 0

Sheet kazatürü
B1: Ayrıntılı Neden | C1: Adet | D1: %
B2: 01 - GÖÇÜK / TAŞ-KÖMÜR DÜŞMESİ /KAYMA
B3: Tavandan taş/kömür düşmesi | C3: =program!V3 -> 0 | D3: =IFERROR(C3/C130*100,0) -> 0
B4: Yan duvar/kanat düşmesi | C4: =program!V4 -> 0 | D4: =IFERROR(C4/C130*100,0) -> 0
B5: Ayna göçüğü / Ayna düşmesi | C5: =program!V5 -> 0 | D5: =IFERROR(C5/C130*100,0) -> 0
B6: Topuk/Ayak göçüğü | C6: =program!V6 -> 0 | D6: =IFERROR(C6/C130*100,0) -> 0
B7: Açık ocak şev kayması/göçüğü | C7: =program!V7 -> 0 | D7: =IFERROR(C7/C130*100,0) -> 0
B8: Dolgu/Tavan arası çökmesi | C8: =program!V8 -> 0 | D8: =IFERROR(C8/C130*100,0) -> 0
B9: Diğer göçük/düşme olayları | C9: =program!V9 -> 0 | D9: =IFERROR(C9/C130*100,0) -> 0
B10: 02 - MALZEME DÜŞMESİ / SIKIŞMA / EZİLME
B11: Malzeme arası sıkışma (el/parmak) | C11: =program!V11 -> 0 | D11: =IFERROR(C11/C130*100,0) -> 0
B12: Makine/ekipman parçası düşmesi | C12: =program!V12 -> 1 | D12: =IFERROR(C12/C130*100,0) -> 11.111111
B13: Tahkimat malzemesi düşmesi | C13: =program!V13 -> 0 | D13: =IFERROR(C13/C130*100,0) -> 0
B14: Dönen/hareketli parçaya kapılma | C14: =program!V14 -> 0 | D14: =IFERROR(C14/C130*100,0) -> 0
B15: Konveyör/bant kazası - Kapılma | C15: =program!V15 -> 0 | D15: =IFERROR(C15/C130*100,0) -> 0
B16: Yükleme/boşaltma sırasında ezilme | C16: =program!V16 -> 0 | D16: =IFERROR(C16/C130*100,0) -> 0
B17: Diğer malzeme düşmesi/sıkışma | C17: =program!V17 -> 0 | D17: =IFERROR(C17/C130*100,0) -> 0
B18: 03 - DÜŞME KİŞİ
B19: Yürürken düşme / Aynı seviye | C19: =program!V19 -> 0 | D19: =IFERROR(C19/C130*100,0) -> 0
B20: Yüksekten düşme - Platform/Merdiven | C20: =program!V20 -> 0 | D20: =IFERROR(C20/C130*100,0) -> 0
B21: Boşluğa/kanala düşme - Hendek | C21: =program!V21 -> 0 | D21: =IFERROR(C21/C130*100,0) -> 0
B22: Araçtan/iş makinesinden düşme | C22: =program!V22 -> 2 | D22: =IFERROR(C22/C130*100,0) -> 22.222222
B23: Kuyu/eğimli kuyu içi düşme | C23: =program!V23 -> 0 | D23: =IFERROR(C23/C130*100,0) -> 0
B24: Duran nesneye çarpıp/takılıp düşme | C24: =program!V24 -> 0 | D24: =IFERROR(C24/C130*100,0) -> 0
B25: El aleti ile çalışırken düşme | C25: =program!V25 -> 0 | D25: =IFERROR(C25/C130*100,0) -> 0
B26: Diğer kişi düşme olayları | C26: =program!V26 -> 1 | D26: =IFERROR(C26/C130*100,0) -> 11.111111
B27: 04 - ÇARPMA / VURMA / BATMA
B28: Aletle çalışırken kendine vurma/çarpma/kesme | C28: =program!V28 -> 0 | D28: =IFERROR(C28/C130*100,0) -> 0
B29: Makine/iş makinesi çarpması | C29: =program!V29 -> 0 | D29: =IFERROR(C29/C130*100,0) -> 0
B30: Tel/çapak/kıymık batması - Sıçrama | C30: =program!V30 -> 0 | D30: =IFERROR(C30/C130*100,0) -> 0
B31: Sabit nesneye çarpma - Tavan/Dikme | C31: =program!V31 -> 1 | D31: =IFERROR(C31/C130*100,0) -> 11.111111
B32: Fırlayan/sıçrayan parça | C32: =program!V32 -> 0 | D32: =IFERROR(C32/C130*100,0) -> 0
B33: Basınçlı madde/su sıçraması | C33: =program!V33 -> 1 | D33: =IFERROR(C33/C130*100,0) -> 11.111111
B34: Diğer çarpma/vurma olayları | C34: =program!V34 -> 0 | D34: =IFERROR(C34/C130*100,0) -> 0
B35: 05 - MOTORLU NAKLİYE / ARAÇ
B36: Servis aracı kazası - Devrilme | C36: =program!V36 -> 0 | D36: =IFERROR(C36/C130*100,0) -> 0
B37: İş makinası kazası - Dozer/Ekskavatör | C37: =program!V37 -> 0 | D37: =IFERROR(C37/C130*100,0) -> 0
B38: Maden kamyonu kazası - Damperli | C38: =program!V38 -> 0 | D38: =IFERROR(C38/C130*100,0) -> 0
B39: Vagon/araba kayması - Fren | C39: =program!V39 -> 0 | D39: =IFERROR(C39/C130*100,0) -> 0
B40: Kulikar/monoray kazası | C40: =program!V40 -> 0 | D40: =IFERROR(C40/C130*100,0) -> 0
...

Sheet kazatürüyer
A2: KAZA | B2: YERALTI | N2: YERÜSTÜ
A3: NEDENİ | B3: Ayak içi/Pano | C3: Hazırlık galerisi | D3: Kömür baca/yolu | E3: Ana ihraç yolu | F3: Bant boyu | G3: Kuyu | H3: Vinç altı | I3: Tertip odası | J3: Kavşak | K3: Havalandırma | L3: Dolgu | M3: YA Diğer | N3: Tesisler | O3: Açık ocak | P3: Atölyeler | Q3: Pazarlama/Kantar | R3: Sosyal tes. | S3: Servis yolu | T3: Laboratuvar | U3: Pasa döküm | V3: Malzeme deposu | W3: Bant hattı | X3: Park/Garaj | Y3: YÜ Diğer | Z3: TOPLAM | AA3: %
A4: GÖÇÜK, TAŞ VEYA KÖMÜR DÜŞ | B4: =COUNTIFS(veri!H:H,11,veri!I:I,">=100",veri!I:I,"<200") -> 0 | C4: =COUNTIFS(veri!H:H,12,veri!I:I,">=100",veri!I:I,"<200") -> 0 | D4: =COUNTIFS(veri!H:H,13,veri!I:I,">=100",veri!I:I,"<200") -> 0 | E4: =COUNTIFS(veri!H:H,14,veri!I:I,">=100",veri!I:I,"<200") -> 0 | F4: =COUNTIFS(veri!H:H,15,veri!I:I,">=100",veri!I:I,"<200") -> 0 | G4: =COUNTIFS(veri!H:H,16,veri!I:I,">=100",veri!I:I,"<200") -> 0 | H4: =COUNTIFS(veri!H:H,17,veri!I:I,">=100",veri!I:I,"<200") -> 0 | I4: =COUNTIFS(veri!H:H,18,veri!I:I,">=100",veri!I:I,"<200") -> 0 | J4: =COUNTIFS(veri!H:H,19,veri!I:I,">=100",veri!I:I,"<200") -> 0 | K4: =COUNTIFS(veri!H:H,20,veri!I:I,">=100",veri!I:I,"<200") -> 0 | L4: =COUNTIFS(veri!H:H,21,veri!I:I,">=100",veri!I:I,"<200") -> 0 | M4: =COUNTIFS(veri!H:H,22,veri!I:I,">=100",veri!I:I,"<200") -> 0 | N4: =COUNTIFS(veri!H:H,31,veri!I:I,">=100",veri!I:I,"<200") -> 0 | O4: =COUNTIFS(veri!H:H,32,veri!I:I,">=100",veri!I:I,"<200") -> 0 | P4: =COUNTIFS(veri!H:H,33,veri!I:I,">=100",veri!I:I,"<200") -> 0 | Q4: =COUNTIFS(veri!H:H,34,veri!I:I,">=100",veri!I:I,"<200") -> 0 | R4: =COUNTIFS(veri!H:H,35,veri!I:I,">=100",veri!I:I,"<200") -> 0 | S4: =COUNTIFS(veri!H:H,36,veri!I:I,">=100",veri!I:I,"<200") -> 0 | T4: =COUNTIFS(veri!H:H,37,veri!I:I,">=100",veri!I:I,"<200") -> 0 | U4: =COUNTIFS(veri!H:H,38,veri!I:I,">=100",veri!I:I,"<200") -> 0 | V4: =COUNTIFS(veri!H:H,39,veri!I:I,">=100",veri!I:I,"<200") -> 0 | W4: =COUNTIFS(veri!H:H,40,veri!I:I,">=100",veri!I:I,"<200") -> 0 | X4: =COUNTIFS(veri!H:H,41,veri!I:I,">=100",veri!I:I,"<200") -> 0 | Y4: =COUNTIFS(veri!H:H,42,veri!I:I,">=100",veri!I:I,"<200") -> 0 | Z4: =SUM(B4:Y4) -> 0
A5: MALZEME DÜŞMESİ / SIKIŞMA | B5: =COUNTIFS(veri!H:H,11,veri!I:I,">=200",veri!I:I,"<300") -> 0 | C5: =COUNTIFS(veri!H:H,12,veri!I:I,">=200",veri!I:I,"<300") -> 0 | D5: =COUNTIFS(veri!H:H,13,veri!I:I,">=200",veri!I:I,"<300") -> 0 | E5: =COUNTIFS(veri!H:H,14,veri!I:I,">=200",veri!I:I,"<300") -> 0 | F5: =COUNTIFS(veri!H:H,15,veri!I:I,">=200",veri!I:I,"<300") -> 0 | G5: =COUNTIFS(veri!H:H,16,veri!I:I,">=200",veri!I:I,"<300") -> 0 | H5: =COUNTIFS(veri!H:H,17,veri!I:I,">=200",veri!I:I,"<300") -> 0 | I5: =COUNTIFS(veri!H:H,18,veri!I:I,">=200",veri!I:I,"<300") -> 0 | J5: =COUNTIFS(veri!H:H,19,veri!I:I,">=200",veri!I:I,"<300") -> 0 | K5: =COUNTIFS(veri!H:H,20,veri!I:I,">=200",veri!I:I,"<300") -> 0 | L5: =COUNTIFS(veri!H:H,21,veri!I:I,">=200",veri!I:I,"<300") -> 0 | M5: =COUNTIFS(veri!H:H,22,veri!I:I,">=200",veri!I:I,"<300") -> 0 | N5: =COUNTIFS(veri!H:H,31,veri!I:I,">=200",veri!I:I,"<300") -> 0 | O5: =COUNTIFS(veri!H:H,32,veri!I:I,">=200",veri!I:I,"<300") -> 0 | P5: =COUNTIFS(veri!H:H,33,veri!I:I,">=200",veri!I:I,"<300") -> 1 | Q5: =COUNTIFS(veri!H:H,34,veri!I:I,">=200",veri!I:I,"<300") -> 0 | R5: =COUNTIFS(veri!H:H,35,veri!I:I,">=200",veri!I:I,"<300") -> 0 | S5: =COUNTIFS(veri!H:H,36,veri!I:I,">=200",veri!I:I,"<300") -> 0 | T5: =COUNTIFS(veri!H:H,37,veri!I:I,">=200",veri!I:I,"<300") -> 0 | U5: =COUNTIFS(veri!H:H,38,veri!I:I,">=200",veri!I:I,"<300") -> 0 | V5: =COUNTIFS(veri!H:H,39,veri!I:I,">=200",veri!I:I,"<300") -> 0 | W5: =COUNTIFS(veri!H:H,40,veri!I:I,">=200",veri!I:I,"<300") -> 0 | X5: =COUNTIFS(veri!H:H,41,veri!I:I,">=200",veri!I:I,"<300") -> 0 | Y5: =COUNTIFS(veri!H:H,42,veri!I:I,">=200",veri!I:I,"<300") -> 0 | Z5: =SUM(B5:Y5) -> 1
A6: DÜŞME (KİŞİ) | B6: =COUNTIFS(veri!H:H,11,veri!I:I,">=300",veri!I:I,"<400") -> 0 | C6: =COUNTIFS(veri!H:H,12,veri!I:I,">=300",veri!I:I,"<400") -> 0 | D6: =COUNTIFS(veri!H:H,13,veri!I:I,">=300",veri!I:I,"<400") -> 0 | E6: =COUNTIFS(veri!H:H,14,veri!I:I,">=300",veri!I:I,"<400") -> 0 | F6: =COUNTIFS(veri!H:H,15,veri!I:I,">=300",veri!I:I,"<400") -> 0 | G6: =COUNTIFS(veri!H:H,16,veri!I:I,">=300",veri!I:I,"<400") -> 0 | H6: =COUNTIFS(veri!H:H,17,veri!I:I,">=300",veri!I:I,"<400") -> 0 | I6: =COUNTIFS(veri!H:H,18,veri!I:I,">=300",veri!I:I,"<400") -> 0 | J6: =COUNTIFS(veri!H:H,19,veri!I:I,">=300",veri!I:I,"<400") -> 0 | K6: =COUNTIFS(veri!H:H,20,veri!I:I,">=300",veri!I:I,"<400") -> 0 | L6: =COUNTIFS(veri!H:H,21,veri!I:I,">=300",veri!I:I,"<400") -> 0 | M6: =COUNTIFS(veri!H:H,22,veri!I:I,">=300",veri!I:I,"<400") -> 0 | N6: =COUNTIFS(veri!H:H,31,veri!I:I,">=300",veri!I:I,"<400") -> 0 | O6: =COUNTIFS(veri!H:H,32,veri!I:I,">=300",veri!I:I,"<400") -> 1 | P6: =COUNTIFS(veri!H:H,33,veri!I:I,">=300",veri!I:I,"<400") -> 0 | Q6: =COUNTIFS(veri!H:H,34,veri!I:I,">=300",veri!I:I,"<400") -> 0 | R6: =COUNTIFS(veri!H:H,35,veri!I:I,">=300",veri!I:I,"<400") -> 1 | S6: =COUNTIFS(veri!H:H,36,veri!I:I,">=300",veri!I:I,"<400") -> 0 | T6: =COUNTIFS(veri!H:H,37,veri!I:I,">=300",veri!I:I,"<400") -> 0 | U6: =COUNTIFS(veri!H:H,38,veri!I:I,">=300",veri!I:I,"<400") -> 0 | V6: =COUNTIFS(veri!H:H,39,veri!I:I,">=300",veri!I:I,"<400") -> 0 | W6: =COUNTIFS(veri!H:H,40,veri!I:I,">=300",veri!I:I,"<400") -> 0 | X6: =COUNTIFS(veri!H:H,41,veri!I:I,">=300",veri!I:I,"<400") -> 1 | Y6: =COUNTIFS(veri!H:H,42,veri!I:I,">=300",veri!I:I,"<400") -> 0 | Z6: =SUM(B6:Y6) -> 3
A7: ÇARPMA / VURMA | B7: =COUNTIFS(veri!H:H,11,veri!I:I,">=400",veri!I:I,"<500") -> 0 | C7: =COUNTIFS(veri!H:H,12,veri!I:I,">=400",veri!I:I,"<500") -> 0 | D7: =COUNTIFS(veri!H:H,13,veri!I:I,">=400",veri!I:I,"<500") -> 0 | E7: =COUNTIFS(veri!H:H,14,veri!I:I,">=400",veri!I:I,"<500") -> 0 | F7: =COUNTIFS(veri!H:H,15,veri!I:I,">=400",veri!I:I,"<500") -> 0 | G7: =COUNTIFS(veri!H:H,16,veri!I:I,">=400",veri!I:I,"<500") -> 0 | H7: =COUNTIFS(veri!H:H,17,veri!I:I,">=400",veri!I:I,"<500") -> 0 | I7: =COUNTIFS(veri!H:H,18,veri!I:I,">=400",veri!I:I,"<500") -> 0 | J7: =COUNTIFS(veri!H:H,19,veri!I:I,">=400",veri!I:I,"<500") -> 0 | K7: =COUNTIFS(veri!H:H,20,veri!I:I,">=400",veri!I:I,"<500") -> 0 | L7: =COUNTIFS(veri!H:H,21,veri!I:I,">=400",veri!I:I,"<500") -> 0 | M7: =COUNTIFS(veri!H:H,22,veri!I:I,">=400",veri!I:I,"<500") -> 0 | N7: =COUNTIFS(veri!H:H,31,veri!I:I,">=400",veri!I:I,"<500") -> 0 | O7: =COUNTIFS(veri!H:H,32,veri!I:I,">=400",veri!I:I,"<500") -> 0 | P7: =COUNTIFS(veri!H:H,33,veri!I:I,">=400",veri!I:I,"<500") -> 2 | Q7: =COUNTIFS(veri!H:H,34,veri!I:I,">=400",veri!I:I,"<500") -> 0 | R7: =COUNTIFS(veri!H:H,35,veri!I:I,">=400",veri!I:I,"<500") -> 0 | S7: =COUNTIFS(veri!H:H,36,veri!I:I,">=400",veri!I:I,"<500") -> 0 | T7: =COUNTIFS(veri!H:H,37,veri!I:I,">=400",veri!I:I,"<500") -> 0 | U7: =COUNTIFS(veri!H:H,38,veri!I:I,">=400",veri!I:I,"<500") -> 0 | V7: =COUNTIFS(veri!H:H,39,veri!I:I,">=400",veri!I:I,"<500") -> 0 | W7: =COUNTIFS(veri!H:H,40,veri!I:I,">=400",veri!I:I,"<500") -> 0 | X7: =COUNTIFS(veri!H:H,41,veri!I:I,">=400",veri!I:I,"<500") -> 0 | Y7: =COUNTIFS(veri!H:H,42,veri!I:I,">=400",veri!I:I,"<500") -> 0 | Z7: =SUM(B7:Y7) -> 2
A8: MOTORLU NAKLİYE / ARAÇ KA | B8: =COUNTIFS(veri!H:H,11,veri!I:I,">=500",veri!I:I,"<600") -> 0 | C8: =COUNTIFS(veri!H:H,12,veri!I:I,">=500",veri!I:I,"<600") -> 0 | D8: =COUNTIFS(veri!H:H,13,veri!I:I,">=500",veri!I:I,"<600") -> 0 | E8: =COUNTIFS(veri!H:H,14,veri!I:I,">=500",veri!I:I,"<600") -> 0 | F8: =COUNTIFS(veri!H:H,15,veri!I:I,">=500",veri!I:I,"<600") -> 0 | G8: =COUNTIFS(veri!H:H,16,veri!I:I,">=500",veri!I:I,"<600") -> 0 | H8: =COUNTIFS(veri!H:H,17,veri!I:I,">=500",veri!I:I,"<600") -> 0 | I8: =COUNTIFS(veri!H:H,18,veri!I:I,">=500",veri!I:I,"<600") -> 0 | J8: =COUNTIFS(veri!H:H,19,veri!I:I,">=500",veri!I:I,"<600") -> 0 | K8: =COUNTIFS(veri!H:H,20,veri!I:I,">=500",veri!I:I,"<600") -> 0 | L8: =COUNTIFS(veri!H:H,21,veri!I:I,">=500",veri!I:I,"<600") -> 0 | M8: =COUNTIFS(veri!H:H,22,veri!I:I,">=500",veri!I:I,"<600") -> 0 | N8: =COUNTIFS(veri!H:H,31,veri!I:I,">=500",veri!I:I,"<600") -> 0 | O8: =COUNTIFS(veri!H:H,32,veri!I:I,">=500",veri!I:I,"<600") -> 0 | P8: =COUNTIFS(veri!H:H,33,veri!I:I,">=500",veri!I:I,"<600") -> 0 | Q8: =COUNTIFS(veri!H:H,34,veri!I:I,">=500",veri!I:I,"<600") -> 0 | R8: =COUNTIFS(veri!H:H,35,veri!I:I,">=500",veri!I:I,"<600") -> 0 | S8: =COUNTIFS(veri!H:H,36,veri!I:I,">=500",veri!I:I,"<600") -> 0 | T8: =COUNTIFS(veri!H:H,37,veri!I:I,">=500",veri!I:I,"<600") -> 0 | U8: =COUNTIFS(veri!H:H,38,veri!I:I,">=500",veri!I:I,"<600") -> 0 | V8: =COUNTIFS(veri!H:H,39,veri!I:I,">=500",veri!I:I,"<600") -> 0 | W8: =COUNTIFS(veri!H:H,40,veri!I:I,">=500",veri!I:I,"<600") -> 0 | X8: =COUNTIFS(veri!H:H,41,veri!I:I,">=500",veri!I:I,"<600") -> 0 | Y8: =COUNTIFS(veri!H:H,42,veri!I:I,">=500",veri!I:I,"<600") -> 0 | Z8: =SUM(B8:Y8) -> 0
A9: MOTORSUZ NAKLİYE | B9: =COUNTIFS(veri!H:H,11,veri!I:I,">=600",veri!I:I,"<700") -> 0 | C9: =COUNTIFS(veri!H:H,12,veri!I:I,">=600",veri!I:I,"<700") -> 0 | D9: =COUNTIFS(veri!H:H,13,veri!I:I,">=600",veri!I:I,"<700") -> 0 | E9: =COUNTIFS(veri!H:H,14,veri!I:I,">=600",veri!I:I,"<700") -> 0 | F9: =COUNTIFS(veri!H:H,15,veri!I:I,">=600",veri!I:I,"<700") -> 0 | G9: =COUNTIFS(veri!H:H,16,veri!I:I,">=600",veri!I:I,"<700") -> 0 | H9: =COUNTIFS(veri!H:H,17,veri!I:I,">=600",veri!I:I,"<700") -> 0 | I9: =COUNTIFS(veri!H:H,18,veri!I:I,">=600",veri!I:I,"<700") -> 0 | J9: =COUNTIFS(veri!H:H,19,veri!I:I,">=600",veri!I:I,"<700") -> 0 | K9: =COUNTIFS(veri!H:H,20,veri!I:I,">=600",veri!I:I,"<700") -> 0 | L9: =COUNTIFS(veri!H:H,21,veri!I:I,">=600",veri!I:I,"<700") -> 0 | M9: =COUNTIFS(veri!H:H,22,veri!I:I,">=600",veri!I:I,"<700") -> 0 | N9: =COUNTIFS(veri!H:H,31,veri!I:I,">=600",veri!I:I,"<700") -> 0 | O9: =COUNTIFS(veri!H:H,32,veri!I:I,">=600",veri!I:I,"<700") -> 0 | P9: =COUNTIFS(veri!H:H,33,veri!I:I,">=600",veri!I:I,"<700") -> 0 | Q9: =COUNTIFS(veri!H:H,34,veri!I:I,">=600",veri!I:I,"<700") -> 0 | R9: =COUNTIFS(veri!H:H,35,veri!I:I,">=600",veri!I:I,"<700") -> 0 | S9: =COUNTIFS(veri!H:H,36,veri!I:I,">=600",veri!I:I,"<700") -> 0 | T9: =COUNTIFS(veri!H:H,37,veri!I:I,">=600",veri!I:I,"<700") -> 0 | U9: =COUNTIFS(veri!H:H,38,veri!I:I,">=600",veri!I:I,"<700") -> 0 | V9: =COUNTIFS(veri!H:H,39,veri!I:I,">=600",veri!I:I,"<700") -> 0 | W9: =COUNTIFS(veri!H:H,40,veri!I:I,">=600",veri!I:I,"<700") -> 0 | X9: =COUNTIFS(veri!H:H,41,veri!I:I,">=600",veri!I:I,"<700") -> 0 | Y9: =COUNTIFS(veri!H:H,42,veri!I:I,">=600",veri!I:I,"<700") -> 0 | Z9: =SUM(B9:Y9) -> 0
A10: VİNÇ / KALDIRMA | B10: =COUNTIFS(veri!H:H,11,veri!I:I,">=700",veri!I:I,"<800") -> 0 | C10: =COUNTIFS(veri!H:H,12,veri!I:I,">=700",veri!I:I,"<800") -> 0 | D10: =COUNTIFS(veri!H:H,13,veri!I:I,">=700",veri!I:I,"<800") -> 0 | E10: =COUNTIFS(veri!H:H,14,veri!I:I,">=700",veri!I:I,"<800") -> 0 | F10: =COUNTIFS(veri!H:H,15,veri!I:I,">=700",veri!I:I,"<800") -> 0 | G10: =COUNTIFS(veri!H:H,16,veri!I:I,">=700",veri!I:I,"<800") -> 0 | H10: =COUNTIFS(veri!H:H,17,veri!I:I,">=700",veri!I:I,"<800") -> 0 | I10: =COUNTIFS(veri!H:H,18,veri!I:I,">=700",veri!I:I,"<800") -> 0 | J10: =COUNTIFS(veri!H:H,19,veri!I:I,">=700",veri!I:I,"<800") -> 0 | K10: =COUNTIFS(veri!H:H,20,veri!I:I,">=700",veri!I:I,"<800") -> 0 | L10: =COUNTIFS(veri!H:H,21,veri!I:I,">=700",veri!I:I,"<800") -> 0 | M10: =COUNTIFS(veri!H:H,22,veri!I:I,">=700",veri!I:I,"<800") -> 0 | N10: =COUNTIFS(veri!H:H,31,veri!I:I,">=700",veri!I:I,"<800") -> 0 | O10: =COUNTIFS(veri!H:H,32,veri!I:I,">=700",veri!I:I,"<800") -> 0 | P10: =COUNTIFS(veri!H:H,33,veri!I:I,">=700",veri!I:I,"<800") -> 0 | Q10: =COUNTIFS(veri!H:H,34,veri!I:I,">=700",veri!I:I,"<800") -> 0 | R10: =COUNTIFS(veri!H:H,35,veri!I:I,">=700",veri!I:I,"<800") -> 0 | S10: =COUNTIFS(veri!H:H,36,veri!I:I,">=700",veri!I:I,"<800") -> 0 | T10: =COUNTIFS(veri!H:H,37,veri!I:I,">=700",veri!I:I,"<800") -> 0 | U10: =COUNTIFS(veri!H:H,38,veri!I:I,">=700",veri!I:I,"<800") -> 0 | V10: =COUNTIFS(veri!H:H,39,veri!I:I,">=700",veri!I:I,"<800") -> 0 | W10: =COUNTIFS(veri!H:H,40,veri!I:I,">=700",veri!I:I,"<800") -> 0 | X10: =COUNTIFS(veri!H:H,41,veri!I:I,">=700",veri!I:I,"<800") -> 0 | Y10: =COUNTIFS(veri!H:H,42,veri!I:I,">=700",veri!I:I,"<800") -> 0 | Z10: =SUM(B10:Y10) -> 0
A11: MAKİNE KAZASI | B11: =COUNTIFS(veri!H:H,11,veri!I:I,">=800",veri!I:I,"<900") -> 0 | C11: =COUNTIFS(veri!H:H,12,veri!I:I,">=800",veri!I:I,"<900") -> 0 | D11: =COUNTIFS(veri!H:H,13,veri!I:I,">=800",veri!I:I,"<900") -> 0 | E11: =COUNTIFS(veri!H:H,14,veri!I:I,">=800",veri!I:I,"<900") -> 0 | F11: =COUNTIFS(veri!H:H,15,veri!I:I,">=800",veri!I:I,"<900") -> 0 | G11: =COUNTIFS(veri!H:H,16,veri!I:I,">=800",veri!I:I,"<900") -> 0 | H11: =COUNTIFS(veri!H:H,17,veri!I:I,">=800",veri!I:I,"<900") -> 0 | I11: =COUNTIFS(veri!H:H,18,veri!I:I,">=800",veri!I:I,"<900") -> 0 | J11: =COUNTIFS(veri!H:H,19,veri!I:I,">=800",veri!I:I,"<900") -> 0 | K11: =COUNTIFS(veri!H:H,20,veri!I:I,">=800",veri!I:I,"<900") -> 0 | L11: =COUNTIFS(veri!H:H,21,veri!I:I,">=800",veri!I:I,"<900") -> 0 | M11: =COUNTIFS(veri!H:H,22,veri!I:I,">=800",veri!I:I,"<900") -> 0 | N11: =COUNTIFS(veri!H:H,31,veri!I:I,">=800",veri!I:I,"<900") -> 0 | O11: =COUNTIFS(veri!H:H,32,veri!I:I,">=800",veri!I:I,"<900") -> 0 | P11: =COUNTIFS(veri!H:H,33,veri!I:I,">=800",veri!I:I,"<900") -> 0 | Q11: =COUNTIFS(veri!H:H,34,veri!I:I,">=800",veri!I:I,"<900") -> 0 | R11: =COUNTIFS(veri!H:H,35,veri!I:I,">=800",veri!I:I,"<900") -> 0 | S11: =COUNTIFS(veri!H:H,36,veri!I:I,">=800",veri!I:I,"<900") -> 0 | T11: =COUNTIFS(veri!H:H,37,veri!I:I,">=800",veri!I:I,"<900") -> 0 | U11: =COUNTIFS(veri!H:H,38,veri!I:I,">=800",veri!I:I,"<900") -> 0 | V11: =COUNTIFS(veri!H:H,39,veri!I:I,">=800",veri!I:I,"<900") -> 0 | W11: =COUNTIFS(veri!H:H,40,veri!I:I,">=800",veri!I:I,"<900") -> 0 | X11: =COUNTIFS(veri!H:H,41,veri!I:I,">=800",veri!I:I,"<900") -> 0 | Y11: =COUNTIFS(veri!H:H,42,veri!I:I,">=800",veri!I:I,"<900") -> 0 | Z11: =SUM(B11:Y11) -> 0
A12: ELEKTRİK KAZASI | B12: =COUNTIFS(veri!H:H,11,veri!I:I,">=900",veri!I:I,"<1000") -> 0 | C12: =COUNTIFS(veri!H:H,12,veri!I:I,">=900",veri!I:I,"<1000") -> 0 | D12: =COUNTIFS(veri!H:H,13,veri!I:I,">=900",veri!I:I,"<1000") -> 0 | E12: =COUNTIFS(veri!H:H,14,veri!I:I,">=900",veri!I:I,"<1000") -> 0 | F12: =COUNTIFS(veri!H:H,15,veri!I:I,">=900",veri!I:I,"<1000") -> 0 | G12: =COUNTIFS(veri!H:H,16,veri!I:I,">=900",veri!I:I,"<1000") -> 0 | H12: =COUNTIFS(veri!H:H,17,veri!I:I,">=900",veri!I:I,"<1000") -> 0 | I12: =COUNTIFS(veri!H:H,18,veri!I:I,">=900",veri!I:I,"<1000") -> 0 | J12: =COUNTIFS(veri!H:H,19,veri!I:I,">=900",veri!I:I,"<1000") -> 0 | K12: =COUNTIFS(veri!H:H,20,veri!I:I,">=900",veri!I:I,"<1000") -> 0 | L12: =COUNTIFS(veri!H:H,21,veri!I:I,">=900",veri!I:I,"<1000") -> 0 | M12: =COUNTIFS(veri!H:H,22,veri!I:I,">=900",veri!I:I,"<1000") -> 0 | N12: =COUNTIFS(veri!H:H,31,veri!I:I,">=900",veri!I:I,"<1000") -> 0 | O12: =COUNTIFS(veri!H:H,32,veri!I:I,">=900",veri!I:I,"<1000") -> 0 | P12: =COUNTIFS(veri!H:H,33,veri!I:I,">=900",veri!I:I,"<1000") -> 0 | Q12: =COUNTIFS(veri!H:H,34,veri!I:I,">=900",veri!I:I,"<1000") -> 0 | R12: =COUNTIFS(veri!H:H,35,veri!I:I,">=900",veri!I:I,"<1000") -> 0 | S12: =COUNTIFS(veri!H:H,36,veri!I:I,">=900",veri!I:I,"<1000") -> 0 | T12: =COUNTIFS(veri!H:H,37,veri!I:I,">=900",veri!I:I,"<1000") -> 0 | U12: =COUNTIFS(veri!H:H,38,veri!I:I,">=900",veri!I:I,"<1000") -> 0 | V12: =COUNTIFS(veri!H:H,39,veri!I:I,">=900",veri!I:I,"<1000") -> 0 | W12: =COUNTIFS(veri!H:H,40,veri!I:I,">=900",veri!I:I,"<1000") -> 0 | X12: =COUNTIFS(veri!H:H,41,veri!I:I,">=900",veri!I:I,"<1000") -> 0 | Y12: =COUNTIFS(veri!H:H,42,veri!I:I,">=900",veri!I:I,"<1000") -> 0 | Z12: =SUM(B12:Y12) -> 0
A13: GAZ VEYA TOZ PATLAMASI | B13: =COUNTIFS(veri!H:H,11,veri!I:I,">=1000",veri!I:I,"<1100") -> 0 | C13: =COUNTIFS(veri!H:H,12,veri!I:I,">=1000",veri!I:I,"<1100") -> 0 | D13: =COUNTIFS(veri!H:H,13,veri!I:I,">=1000",veri!I:I,"<1100") -> 0 | E13: =COUNTIFS(veri!H:H,14,veri!I:I,">=1000",veri!I:I,"<1100") -> 0 | F13: =COUNTIFS(veri!H:H,15,veri!I:I,">=1000",veri!I:I,"<1100") -> 0 | G13: =COUNTIFS(veri!H:H,16,veri!I:I,">=1000",veri!I:I,"<1100") -> 0 | H13: =COUNTIFS(veri!H:H,17,veri!I:I,">=1000",veri!I:I,"<1100") -> 0 | I13: =COUNTIFS(veri!H:H,18,veri!I:I,">=1000",veri!I:I,"<1100") -> 0 | J13: =COUNTIFS(veri!H:H,19,veri!I:I,">=1000",veri!I:I,"<1100") -> 0 | K13: =COUNTIFS(veri!H:H,20,veri!I:I,">=1000",veri!I:I,"<1100") -> 0 | L13: =COUNTIFS(veri!H:H,21,veri!I:I,">=1000",veri!I:I,"<1100") -> 0 | M13: =COUNTIFS(veri!H:H,22,veri!I:I,">=1000",veri!I:I,"<1100") -> 0 | N13: =COUNTIFS(veri!H:H,31,veri!I:I,">=1000",veri!I:I,"<1100") -> 0 | O13: =COUNTIFS(veri!H:H,32,veri!I:I,">=1000",veri!I:I,"<1100") -> 0 | P13: =COUNTIFS(veri!H:H,33,veri!I:I,">=1000",veri!I:I,"<1100") -> 0 | Q13: =COUNTIFS(veri!H:H,34,veri!I:I,">=1000",veri!I:I,"<1100") -> 0 | R13: =COUNTIFS(veri!H:H,35,veri!I:I,">=1000",veri!I:I,"<1100") -> 0 | S13: =COUNTIFS(veri!H:H,36,veri!I:I,">=1000",veri!I:I,"<1100") -> 0 | T13: =COUNTIFS(veri!H:H,37,veri!I:I,">=1000",veri!I:I,"<1100") -> 0 | U13: =COUNTIFS(veri!H:H,38,veri!I:I,">=1000",veri!I:I,"<1100") -> 0 | V13: =COUNTIFS(veri!H:H,39,veri!I:I,">=1000",veri!I:I,"<1100") -> 0 | W13: =COUNTIFS(veri!H:H,40,veri!I:I,">=1000",veri!I:I,"<1100") -> 0 | X13: =COUNTIFS(veri!H:H,41,veri!I:I,">=1000",veri!I:I,"<1100") -> 0 | Y13: =COUNTIFS(veri!H:H,42,veri!I:I,">=1000",veri!I:I,"<1100") -> 0 | Z13: =SUM(B13:Y13) -> 0
A14: YANGIN | B14: =COUNTIFS(veri!H:H,11,veri!I:I,">=1100",veri!I:I,"<1200") -> 0 | C14: =COUNTIFS(veri!H:H,12,veri!I:I,">=1100",veri!I:I,"<1200") -> 0 | D14: =COUNTIFS(veri!H:H,13,veri!I:I,">=1100",veri!I:I,"<1200") -> 0 | E14: =COUNTIFS(veri!H:H,14,veri!I:I,">=1100",veri!I:I,"<1200") -> 0 | F14: =COUNTIFS(veri!H:H,15,veri!I:I,">=1100",veri!I:I,"<1200") -> 0 | G14: =COUNTIFS(veri!H:H,16,veri!I:I,">=1100",veri!I:I,"<1200") -> 0 | H14: =COUNTIFS(veri!H:H,17,veri!I:I,">=1100",veri!I:I,"<1200") -> 0 | I14: =COUNTIFS(veri!H:H,18,veri!I:I,">=1100",veri!I:I,"<1200") -> 0 | J14: =COUNTIFS(veri!H:H,19,veri!I:I,">=1100",veri!I:I,"<1200") -> 0 | K14: =COUNTIFS(veri!H:H,20,veri!I:I,">=1100",veri!I:I,"<1200") -> 0 | L14: =COUNTIFS(veri!H:H,21,veri!I:I,">=1100",veri!I:I,"<1200") -> 0 | M14: =COUNTIFS(veri!H:H,22,veri!I:I,">=1100",veri!I:I,"<1200") -> 0 | N14: =COUNTIFS(veri!H:H,31,veri!I:I,">=1100",veri!I:I,"<1200") -> 0 | O14: =COUNTIFS(veri!H:H,32,veri!I:I,">=1100",veri!I:I,"<1200") -> 2 | P14: =COUNTIFS(veri!H:H,33,veri!I:I,">=1100",veri!I:I,"<1200") -> 0 | Q14: =COUNTIFS(veri!H:H,34,veri!I:I,">=1100",veri!I:I,"<1200") -> 0 | R14: =COUNTIFS(veri!H:H,35,veri!I:I,">=1100",veri!I:I,"<1200") -> 0 | S14: =COUNTIFS(veri!H:H,36,veri!I:I,">=1100",veri!I:I,"<1200") -> 0 | T14: =COUNTIFS(veri!H:H,37,veri!I:I,">=1100",veri!I:I,"<1200") -> 0 | U14: =COUNTIFS(veri!H:H,38,veri!I:I,">=1100",veri!I:I,"<1200") -> 0 | V14: =COUNTIFS(veri!H:H,39,veri!I:I,">=1100",veri!I:I,"<1200") -> 0 | W14: =COUNTIFS(veri!H:H,40,veri!I:I,">=1100",veri!I:I,"<1200") -> 0 | X14: =COUNTIFS(veri!H:H,41,veri!I:I,">=1100",veri!I:I,"<1200") -> 0 | Y14: =COUNTIFS(veri!H:H,42,veri!I:I,">=1100",veri!I:I,"<1200") -> 0 | Z14: =SUM(B14:Y14) -> 2
A15: SU BASKINI / İNÜNDASYON | B15: =COUNTIFS(veri!H:H,11,veri!I:I,">=1200",veri!I:I,"<1300") -> 0 | C15: =COUNTIFS(veri!H:H,12,veri!I:I,">=1200",veri!I:I,"<1300") -> 0 | D15: =COUNTIFS(veri!H:H,13,veri!I:I,">=1200",veri!I:I,"<1300") -> 0 | E15: =COUNTIFS(veri!H:H,14,veri!I:I,">=1200",veri!I:I,"<1300") -> 0 | F15: =COUNTIFS(veri!H:H,15,veri!I:I,">=1200",veri!I:I,"<1300") -> 0 | G15: =COUNTIFS(veri!H:H,16,veri!I:I,">=1200",veri!I:I,"<1300") -> 0 | H15: =COUNTIFS(veri!H:H,17,veri!I:I,">=1200",veri!I:I,"<1300") -> 0 | I15: =COUNTIFS(veri!H:H,18,veri!I:I,">=1200",veri!I:I,"<1300") -> 0 | J15: =COUNTIFS(veri!H:H,19,veri!I:I,">=1200",veri!I:I,"<1300") -> 0 | K15: =COUNTIFS(veri!H:H,20,veri!I:I,">=1200",veri!I:I,"<1300") -> 0 | L15: =COUNTIFS(veri!H:H,21,veri!I:I,">=1200",veri!I:I,"<1300") -> 0 | M15: =COUNTIFS(veri!H:H,22,veri!I:I,">=1200",veri!I:I,"<1300") -> 0 | N15: =COUNTIFS(veri!H:H,31,veri!I:I,">=1200",veri!I:I,"<1300") -> 0 | O15: =COUNTIFS(veri!H:H,32,veri!I:I,">=1200",veri!I:I,"<1300") -> 0 | P15: =COUNTIFS(veri!H:H,33,veri!I:I,">=1200",veri!I:I,"<1300") -> 0 | Q15: =COUNTIFS(veri!H:H,34,veri!I:I,">=1200",veri!I:I,"<1300") -> 0 | R15: =COUNTIFS(veri!H:H,35,veri!I:I,">=1200",veri!I:I,"<1300") -> 0 | S15: =COUNTIFS(veri!H:H,36,veri!I:I,">=1200",veri!I:I,"<1300") -> 0 | T15: =COUNTIFS(veri!H:H,37,veri!I:I,">=1200",veri!I:I,"<1300") -> 0 | U15: =COUNTIFS(veri!H:H,38,veri!I:I,">=1200",veri!I:I,"<1300") -> 0 | V15: =COUNTIFS(veri!H:H,39,veri!I:I,">=1200",veri!I:I,"<1300") -> 0 | W15: =COUNTIFS(veri!H:H,40,veri!I:I,">=1200",veri!I:I,"<1300") -> 0 | X15: =COUNTIFS(veri!H:H,41,veri!I:I,">=1200",veri!I:I,"<1300") -> 0 | Y15: =COUNTIFS(veri!H:H,42,veri!I:I,">=1200",veri!I:I,"<1300") -> 0 | Z15: =SUM(B15:Y15) -> 0
A16: PATLAYICI MADDE KAZASI | B16: =COUNTIFS(veri!H:H,11,veri!I:I,">=1300",veri!I:I,"<1400") -> 0 | C16: =COUNTIFS(veri!H:H,12,veri!I:I,">=1300",veri!I:I,"<1400") -> 0 | D16: =COUNTIFS(veri!H:H,13,veri!I:I,">=1300",veri!I:I,"<1400") -> 0 | E16: =COUNTIFS(veri!H:H,14,veri!I:I,">=1300",veri!I:I,"<1400") -> 0 | F16: =COUNTIFS(veri!H:H,15,veri!I:I,">=1300",veri!I:I,"<1400") -> 0 | G16: =COUNTIFS(veri!H:H,16,veri!I:I,">=1300",veri!I:I,"<1400") -> 0 | H16: =COUNTIFS(veri!H:H,17,veri!I:I,">=1300",veri!I:I,"<1400") -> 0 | I16: =COUNTIFS(veri!H:H,18,veri!I:I,">=1300",veri!I:I,"<1400") -> 0 | J16: =COUNTIFS(veri!H:H,19,veri!I:I,">=1300",veri!I:I,"<1400") -> 0 | K16: =COUNTIFS(veri!H:H,20,veri!I:I,">=1300",veri!I:I,"<1400") -> 0 | L16: =COUNTIFS(veri!H:H,21,veri!I:I,">=1300",veri!I:I,"<1400") -> 0 | M16: =COUNTIFS(veri!H:H,22,veri!I:I,">=1300",veri!I:I,"<1400") -> 0 | N16: =COUNTIFS(veri!H:H,31,veri!I:I,">=1300",veri!I:I,"<1400") -> 0 | O16: =COUNTIFS(veri!H:H,32,veri!I:I,">=1300",veri!I:I,"<1400") -> 0 | P16: =COUNTIFS(veri!H:H,33,veri!I:I,">=1300",veri!I:I,"<1400") -> 0 | Q16: =COUNTIFS(veri!H:H,34,veri!I:I,">=1300",veri!I:I,"<1400") -> 0 | R16: =COUNTIFS(veri!H:H,35,veri!I:I,">=1300",veri!I:I,"<1400") -> 0 | S16: =COUNTIFS(veri!H:H,36,veri!I:I,">=1300",veri!I:I,"<1400") -> 0 | T16: =COUNTIFS(veri!H:H,37,veri!I:I,">=1300",veri!I:I,"<1400") -> 0 | U16: =COUNTIFS(veri!H:H,38,veri!I:I,">=1300",veri!I:I,"<1400") -> 0 | V16: =COUNTIFS(veri!H:H,39,veri!I:I,">=1300",veri!I:I,"<1400") -> 0 | W16: =COUNTIFS(veri!H:H,40,veri!I:I,">=1300",veri!I:I,"<1400") -> 0 | X16: =COUNTIFS(veri!H:H,41,veri!I:I,">=1300",veri!I:I,"<1400") -> 0 | Y16: =COUNTIFS(veri!H:H,42,veri!I:I,">=1300",veri!I:I,"<1400") -> 0 | Z16: =SUM(B16:Y16) -> 0
A17: ELLE TAŞIMA / ZORLANMA | B17: =COUNTIFS(veri!H:H,11,veri!I:I,">=1400",veri!I:I,"<1500") -> 0 | C17: =COUNTIFS(veri!H:H,12,veri!I:I,">=1400",veri!I:I,"<1500") -> 0 | D17: =COUNTIFS(veri!H:H,13,veri!I:I,">=1400",veri!I:I,"<1500") -> 0 | E17: =COUNTIFS(veri!H:H,14,veri!I:I,">=1400",veri!I:I,"<1500") -> 0 | F17: =COUNTIFS(veri!H:H,15,veri!I:I,">=1400",veri!I:I,"<1500") -> 0 | G17: =COUNTIFS(veri!H:H,16,veri!I:I,">=1400",veri!I:I,"<1500") -> 0 | H17: =COUNTIFS(veri!H:H,17,veri!I:I,">=1400",veri!I:I,"<1500") -> 0 | I17: =COUNTIFS(veri!H:H,18,veri!I:I,">=1400",veri!I:I,"<1500") -> 0 | J17: =COUNTIFS(veri!H:H,19,veri!I:I,">=1400",veri!I:I,"<1500") -> 0 | K17: =COUNTIFS(veri!H:H,20,veri!I:I,">=1400",veri!I:I,"<1500") -> 0 | L17: =COUNTIFS(veri!H:H,21,veri!I:I,">=1400",veri!I:I,"<1500") -> 0 | M17: =COUNTIFS(veri!H:H,22,veri!I:I,">=1400",veri!I:I,"<1500") -> 0 | N17: =COUNTIFS(veri!H:H,31,veri!I:I,">=1400",veri!I:I,"<1500") -> 0 | O17: =COUNTIFS(veri!H:H,32,veri!I:I,">=1400",veri!I:I,"<1500") -> 0 | P17: =COUNTIFS(veri!H:H,33,veri!I:I,">=1400",veri!I:I,"<1500") -> 0 | Q17: =COUNTIFS(veri!H:H,34,veri!I:I,">=1400",veri!I:I,"<1500") -> 0 | R17: =COUNTIFS(veri!H:H,35,veri!I:I,">=1400",veri!I:I,"<1500") -> 0 | S17: =COUNTIFS(veri!H:H,36,veri!I:I,">=1400",veri!I:I,"<1500") -> 0 | T17: =COUNTIFS(veri!H:H,37,veri!I:I,">=1400",veri!I:I,"<1500") -> 0 | U17: =COUNTIFS(veri!H:H,38,veri!I:I,">=1400",veri!I:I,"<1500") -> 0 | V17: =COUNTIFS(veri!H:H,39,veri!I:I,">=1400",veri!I:I,"<1500") -> 0 | W17: =COUNTIFS(veri!H:H,40,veri!I:I,">=1400",veri!I:I,"<1500") -> 0 | X17: =COUNTIFS(veri!H:H,41,veri!I:I,">=1400",veri!I:I,"<1500") -> 0 | Y17: =COUNTIFS(veri!H:H,42,veri!I:I,">=1400",veri!I:I,"<1500") -> 0 | Z17: =SUM(B17:Y17) -> 0
A18: MAHSUR KALMA | B18: =COUNTIFS(veri!H:H,11,veri!I:I,">=1500",veri!I:I,"<1600") -> 0 | C18: =COUNTIFS(veri!H:H,12,veri!I:I,">=1500",veri!I:I,"<1600") -> 0 | D18: =COUNTIFS(veri!H:H,13,veri!I:I,">=1500",veri!I:I,"<1600") -> 0 | E18: =COUNTIFS(veri!H:H,14,veri!I:I,">=1500",veri!I:I,"<1600") -> 0 | F18: =COUNTIFS(veri!H:H,15,veri!I:I,">=1500",veri!I:I,"<1600") -> 0 | G18: =COUNTIFS(veri!H:H,16,veri!I:I,">=1500",veri!I:I,"<1600") -> 0 | H18: =COUNTIFS(veri!H:H,17,veri!I:I,">=1500",veri!I:I,"<1600") -> 0 | I18: =COUNTIFS(veri!H:H,18,veri!I:I,">=1500",veri!I:I,"<1600") -> 0 | J18: =COUNTIFS(veri!H:H,19,veri!I:I,">=1500",veri!I:I,"<1600") -> 0 | K18: =COUNTIFS(veri!H:H,20,veri!I:I,">=1500",veri!I:I,"<1600") -> 0 | L18: =COUNTIFS(veri!H:H,21,veri!I:I,">=1500",veri!I:I,"<1600") -> 0 | M18: =COUNTIFS(veri!H:H,22,veri!I:I,">=1500",veri!I:I,"<1600") -> 0 | N18: =COUNTIFS(veri!H:H,31,veri!I:I,">=1500",veri!I:I,"<1600") -> 0 | O18: =COUNTIFS(veri!H:H,32,veri!I:I,">=1500",veri!I:I,"<1600") -> 0 | P18: =COUNTIFS(veri!H:H,33,veri!I:I,">=1500",veri!I:I,"<1600") -> 0 | Q18: =COUNTIFS(veri!H:H,34,veri!I:I,">=1500",veri!I:I,"<1600") -> 0 | R18: =COUNTIFS(veri!H:H,35,veri!I:I,">=1500",veri!I:I,"<1600") -> 0 | S18: =COUNTIFS(veri!H:H,36,veri!I:I,">=1500",veri!I:I,"<1600") -> 0 | T18: =COUNTIFS(veri!H:H,37,veri!I:I,">=1500",veri!I:I,"<1600") -> 0 | U18: =COUNTIFS(veri!H:H,38,veri!I:I,">=1500",veri!I:I,"<1600") -> 0 | V18: =COUNTIFS(veri!H:H,39,veri!I:I,">=1500",veri!I:I,"<1600") -> 0 | W18: =COUNTIFS(veri!H:H,40,veri!I:I,">=1500",veri!I:I,"<1600") -> 0 | X18: =COUNTIFS(veri!H:H,41,veri!I:I,">=1500",veri!I:I,"<1600") -> 0 | Y18: =COUNTIFS(veri!H:H,42,veri!I:I,">=1500",veri!I:I,"<1600") -> 0 | Z18: =SUM(B18:Y18) -> 0
A19: SICAK ÇALIŞMA / KAYNAK | B19: =COUNTIFS(veri!H:H,11,veri!I:I,">=1600",veri!I:I,"<1700") -> 0 | C19: =COUNTIFS(veri!H:H,12,veri!I:I,">=1600",veri!I:I,"<1700") -> 0 | D19: =COUNTIFS(veri!H:H,13,veri!I:I,">=1600",veri!I:I,"<1700") -> 0 | E19: =COUNTIFS(veri!H:H,14,veri!I:I,">=1600",veri!I:I,"<1700") -> 0 | F19: =COUNTIFS(veri!H:H,15,veri!I:I,">=1600",veri!I:I,"<1700") -> 0 | G19: =COUNTIFS(veri!H:H,16,veri!I:I,">=1600",veri!I:I,"<1700") -> 0 | H19: =COUNTIFS(veri!H:H,17,veri!I:I,">=1600",veri!I:I,"<1700") -> 0 | I19: =COUNTIFS(veri!H:H,18,veri!I:I,">=1600",veri!I:I,"<1700") -> 0 | J19: =COUNTIFS(veri!H:H,19,veri!I:I,">=1600",veri!I:I,"<1700") -> 0 | K19: =COUNTIFS(veri!H:H,20,veri!I:I,">=1600",veri!I:I,"<1700") -> 0 | L19: =COUNTIFS(veri!H:H,21,veri!I:I,">=1600",veri!I:I,"<1700") -> 0 | M19: =COUNTIFS(veri!H:H,22,veri!I:I,">=1600",veri!I:I,"<1700") -> 0 | N19: =COUNTIFS(veri!H:H,31,veri!I:I,">=1600",veri!I:I,"<1700") -> 0 | O19: =COUNTIFS(veri!H:H,32,veri!I:I,">=1600",veri!I:I,"<1700") -> 0 | P19: =COUNTIFS(veri!H:H,33,veri!I:I,">=1600",veri!I:I,"<1700") -> 0 | Q19: =COUNTIFS(veri!H:H,34,veri!I:I,">=1600",veri!I:I,"<1700") -> 0 | R19: =COUNTIFS(veri!H:H,35,veri!I:I,">=1600",veri!I:I,"<1700") -> 0 | S19: =COUNTIFS(veri!H:H,36,veri!I:I,">=1600",veri!I:I,"<1700") -> 0 | T19: =COUNTIFS(veri!H:H,37,veri!I:I,">=1600",veri!I:I,"<1700") -> 0 | U19: =COUNTIFS(veri!H:H,38,veri!I:I,">=1600",veri!I:I,"<1700") -> 0 | V19: =COUNTIFS(veri!H:H,39,veri!I:I,">=1600",veri!I:I,"<1700") -> 0 | W19: =COUNTIFS(veri!H:H,40,veri!I:I,">=1600",veri!I:I,"<1700") -> 0 | X19: =COUNTIFS(veri!H:H,41,veri!I:I,">=1600",veri!I:I,"<1700") -> 0 | Y19: =COUNTIFS(veri!H:H,42,veri!I:I,">=1600",veri!I:I,"<1700") -> 0 | Z19: =SUM(B19:Y19) -> 0
